<?xml version="1.0" encoding="UTF-8"?>
<robot name="ur5e">

  <!-- <joint name="root_joint" type="fixed">
    <origin xyz="0. 0. 0." rpy="0. 0. 0."/>
    <parent link="Root"/>
    <child link="base_link"/>
    <limit lower="0." upper="0." effort="0." velocity="0."/>
  </joint> -->

  <joint name="base_link_base_link_inertia" type="fixed">
    <origin xyz="0. 0. 0." rpy="0. 0. -3.1415925"/>
    <parent link="base_link"/>
    <child link="base_link_inertia"/>
    <limit lower="0." upper="0." effort="0." velocity="0."/>
  </joint>

    <joint name="base_link-base_fixed_joint" type="fixed">
    <!-- Note the rotation over Z of pi radians - as base_link is REP-103
           aligned (i.e., has X+ forward, Y+ left and Z+ up), this is needed
           to correctly align 'base' with the 'Base' coordinate system of
           the UR controller.
      -->
    <origin rpy="0 0 3.141592653589793" xyz="0 0 0"/>
    <parent link="base_link"/>
    <child link="base"/>
  </joint>

    <joint name="shoulder_pan_joint" type="revolute">
    <origin xyz="0 0 0.1625" rpy="0. 0. 0."/>
    <parent link="base_link_inertia"/>
    <child link="shoulder_link"/>
    <axis xyz="0. 0. 1."/>
    <limit lower="-6.2831853" upper="6.2831853" effort="150.0" velocity="3.141592653589793"/>
    <safety_controller k_position="20" k_velocity="0.0" soft_lower_limit="-6.133185307179586" soft_upper_limit="6.133185307179586"/>
    <dynamics damping="0" friction="0"/>
  </joint>

  <joint name="shoulder_lift_joint" type="revolute">
    <origin xyz="0. 0. 0." rpy="1.5707964 0. 0. "/>
    <parent link="shoulder_link"/>
    <child link="upper_arm_link"/>
    <axis xyz="0. 0. 1."/>
    <limit lower="-6.2831853" upper="6.2831853" effort="150." velocity="3.141592653589793"/>
    <safety_controller k_position="20" k_velocity="0.0" soft_lower_limit="-6.133185307179586" soft_upper_limit="6.133185307179586"/>
    <dynamics damping="0" friction="0"/>
  </joint>

  <joint name="elbow_joint" type="revolute">
    <origin xyz="-0.425 0. 0. " rpy="0. 0. 0."/>
    <parent link="upper_arm_link"/>
    <child link="forearm_link"/>
    <axis xyz="0. 0. 1."/>
    <limit lower="-3.1415927" upper="3.1415927" effort="150." velocity="3.141592653589793"/>
    <safety_controller k_position="20" k_velocity="0.0" soft_lower_limit="-2.991592653589793" soft_upper_limit="2.991592653589793"/>
    <dynamics damping="0" friction="0"/>
  </joint>

  <joint name="wrist_1_joint" type="revolute">
    <origin xyz="-0.3922 0. 0.1333" rpy="0. 0. 0."/>
    <parent link="forearm_link"/>
    <child link="wrist_1_link"/>
    <axis xyz="0. 0. 1."/>
    <limit lower="-6.2831853" upper="6.2831853" effort="150." velocity="3.141592653589793"/>
    <safety_controller k_position="20" k_velocity="0.0" soft_lower_limit="-2.991592653589793" soft_upper_limit="2.991592653589793"/>
    <dynamics damping="0" friction="0"/>
  </joint>

  <joint name="wrist_2_joint" type="revolute">
    <origin xyz="0. -0.0997 -0. " rpy="1.5707964 0. 0. "/>
    <parent link="wrist_1_link"/>
    <child link="wrist_2_link"/>
    <axis xyz="0. 0. 1."/>
    <limit lower="-6.2831853" upper="6.2831853" effort="150." velocity="3.141592653589793"/>
    <safety_controller k_position="20" k_velocity="0.0" soft_lower_limit="-2.991592653589793" soft_upper_limit="2.991592653589793"/>
    <dynamics damping="0" friction="0"/>
  </joint>

  <joint name="wrist_3_joint" type="revolute">
    <origin xyz="0. 0.0996 -0. " rpy="-1.5707964 -0.0000001 0.0000001"/>
    <parent link="wrist_2_link"/>
    <child link="wrist_3_link"/>
    <axis xyz="0. 0. 1."/>
    <limit lower="-6.2831853" upper="6.2831853" effort="150." velocity="3.141592653589793"/>
    <safety_controller k_position="20" k_velocity="0.0" soft_lower_limit="-2.991592653589793" soft_upper_limit="2.991592653589793"/>
    <dynamics damping="0" friction="0"/>
  </joint>

  <joint name="wrist_3_flange" type="fixed">
    <origin xyz="0. 0. 0." rpy="-1.5707964 -1.5707964 0. "/>
    <parent link="wrist_3_link"/>
    <child link="flange"/>
  </joint>

  <joint name="flange_tool0" type="fixed">
    <origin xyz="0. 0. 0." rpy="1.5707964 0. 1.5707964"/>
    <parent link="flange"/>
    <child link="tool0"/>
  </joint>

 






<!--

  


  


#######################################

  <link name="world"/>


 <joint name="rt_joint0" type="fixed">
    <parent link="flange"/>
    <child link="onrobot_rg2_base_link"/>
    <origin rpy=" 0. 1.5707964 0." xyz="0. 0. 0."/>
  </joint>

  <joint name="left_outer_knuckle_joint" type="revolute">
    <origin rpy="0. 0. 0." xyz="0 -0.017178 0.125797"/>
    <parent link="onrobot_rg2_base_link"/>
    <child link="left_outer_knuckle"/>
    <axis xyz="-1 0 0"/>
    <limit effort="150" lower="-0.558505" upper="0.785398" velocity="3.141592653589793"/>
    <safety_controller k_position="20" k_velocity="0.0" soft_lower_limit="-2.991592653589793" soft_upper_limit="2.991592653589793"/>
    <dynamics damping="0" friction="0"/>

  </joint>


  <joint name="left_inner_knuckle_joint" type="revolute">
    <origin rpy="0. 0. 0." xyz="0 -0.007678 0.1422970"/>
    <parent link="onrobot_rg2_base_link"/>
    <child link="left_inner_knuckle"/>
    <axis xyz="1 0 0"/>
    <limit effort="1000" lower="-0.558505" upper="0.785398" velocity="100"/>
    <mimic joint="left_outer_knuckle_joint" multiplier="-1" offset="0"/>
    
  </joint>


  <joint name="left_outer_finger_joint" type="revolute">
    <origin rpy="0 0 0" xyz="0 -0.039592 0.038177000000000016"/>
    <parent link="left_outer_knuckle"/>
    <child link="left_inner_finger"/>
    <axis xyz="1 0 0"/>
    <limit effort="1000" lower="-0.558505" upper="0.785398" velocity="100"/>
    <mimic joint="left_outer_knuckle_joint" multiplier="1" offset="0"/>
  </joint>

    <joint name="right_outer_knuckle_joint" type="revolute">
    <origin rpy="0 0 3.141592653589793" xyz="0 0.017178 0.125797"/>
    <parent link="onrobot_rg2_base_link"/>
    <child link="right_outer_knuckle"/>
    <axis xyz="1 0 0"/>
    <limit effort="1000" lower="-0.785398" upper="0.785398" velocity="100.0"/>
    <mimic joint="left_outer_knuckle_joint" multiplier="-1" offset="0"/>
  </joint>
  <joint name="right_inner_knuckle_joint" type="revolute">
    <origin rpy="0 0 -3.141592653589793" xyz="0 0.007678 0.1422970"/>
    <parent link="onrobot_rg2_base_link"/>
    <child link="right_inner_knuckle"/>
    <axis xyz="1 0 0"/>
    <limit effort="1000" lower="-0.785398" upper="0.785398" velocity="100.0"/>
    <mimic joint="left_outer_knuckle_joint" multiplier="-1" offset="0"/>
  </joint>


  <joint name="right_inner_finger_joint" type="revolute">
    <origin rpy="0 0 0" xyz="0 -0.039592 0.038177000000000016"/>
    <parent link="right_outer_knuckle"/>
    <child link="right_inner_finger"/>
    <axis xyz="1 0 0"/>
    <limit effort="1000" lower="-0.872665" upper="0.872665" velocity="100.0"/>
    <mimic joint="left_outer_knuckle_joint" multiplier="1" offset="0"/>
  </joint>



 

   





  
<link name="onrobot_rg2_base_link">
    <inertial>
      <origin rpy="0 0 0" xyz="0.0 0.0 0.0"/>
      <mass value="0.7"/>
      <inertia ixx="1.0E-03" ixy="1.0E-06" ixz="1.0E-06" iyy="1.0E-03" iyz="1.0E-06" izz="1.0E-03"/>
    </inertial>
    <visual>
      <origin rpy="0 0 0" xyz="0 0 0"/>
      <geometry>
        <mesh filename="meshes/rg2/visual/base_link.stl"/>
      </geometry>
      <material name="">
        <color rgba="0.8 0.8 0.8 1"/>
      </material>
    </visual>
    <collision>
      <origin rpy="0 0 0" xyz="0 0 0"/>
      <geometry>
        <mesh filename="meshes/rg2/collision/base_link.stl"/>
      </geometry>
    </collision>
  </link>

   <link name="left_outer_knuckle">
    <inertial>
      <origin rpy="0 0 0" xyz="0.0 0.0 0.0"/>
      <mass value="0.05"/>
      <inertia ixx="1.0E-03" ixy="1.0E-06" ixz="1.0E-06" iyy="1.0E-03" iyz="1.0E-06" izz="1.0E-03"/>
    </inertial>
    <visual>
      <origin rpy="0 0 0" xyz="0 0 0"/>
      <geometry>
        <mesh filename="meshes/rg2/visual/outer_knuckle.stl"/>
      </geometry>
      <material name="">
        <color rgba="0.8 0.8 0.8 1"/>
      </material>
    </visual>
    <collision>
      <origin rpy="0 0 0" xyz="0 0 0"/>
      <geometry>
        <mesh filename="meshes/rg2/collision/outer_knuckle.stl"/>
      </geometry>
    </collision>
  </link>

  <link name="left_inner_knuckle">
    <inertial>
      <origin rpy="0 0 0" xyz="0.0 0.0 0.0"/>
      <mass value="0.05"/>
      <inertia ixx="1.0E-03" ixy="1.0E-06" ixz="1.0E-06" iyy="1.0E-03" iyz="1.0E-06" izz="1.0E-03"/>
    </inertial>
    <visual>
      <origin rpy="0 0 0" xyz="0 0 0"/>
      <geometry>
        <mesh filename="meshes/rg2/visual/inner_knuckle.stl"/>
      </geometry>
      <material name="">
        <color rgba="0.8 0.8 0.8 1"/>
      </material>
    </visual>
    <collision>
      <origin rpy="0 0 0" xyz="0 0 0"/>
      <geometry>
        <mesh filename="meshes/rg2/collision/inner_knuckle.stl"/>
      </geometry>
    </collision>
  </link>

<link name="left_inner_finger">
    <inertial>
      <origin rpy="0 0 0" xyz="0.0 0.0 0.0"/>
      <mass value="0.05"/>
      <inertia ixx="1.0E-03" ixy="1.0E-06" ixz="1.0E-06" iyy="1.0E-03" iyz="1.0E-06" izz="1.0E-03"/>
    </inertial>
    <visual>
      <origin rpy="0 0 0" xyz="0 0 0"/>
      <geometry>
        <mesh filename="meshes/rg2/visual/inner_finger.stl"/>
      </geometry>
      <material name="">
        <color rgba="0.1 0.1 0.1 1"/>
      </material>
    </visual>

</link>

<link name="right_outer_knuckle">
    <inertial>
      <origin rpy="0 0 0" xyz="0.0 0.0 0.0"/>
      <mass value="0.05"/>
      <inertia ixx="1.0E-03" ixy="1.0E-06" ixz="1.0E-06" iyy="1.0E-03" iyz="1.0E-06" izz="1.0E-03"/>
    </inertial>
    <visual>
      <origin rpy="0 0 0" xyz="0 0 0"/>
      <geometry>
        <mesh filename="meshes/rg2/visual/outer_knuckle.stl"/>
      </geometry>
      <material name="">
        <color rgba="0.8 0.8 0.8 1"/>
      </material>
    </visual>
    <collision>
      <origin rpy="0 0 0" xyz="0 0 0"/>
      <geometry>
        <mesh filename="meshes/rg2/collision/outer_knuckle.stl"/>
      </geometry>
    </collision>
  </link>

  <link name="right_inner_knuckle">
    <inertial>
      <origin rpy="0 0 0" xyz="0.0 0.0 0.0"/>
      <mass value="0.05"/>
      <inertia ixx="1.0E-03" ixy="1.0E-06" ixz="1.0E-06" iyy="1.0E-03" iyz="1.0E-06" izz="1.0E-03"/>
    </inertial>
    <visual>
      <origin rpy="0 0 0" xyz="0 0 0"/>
      <geometry>
        <mesh filename="meshes/rg2/visual/inner_knuckle.stl"/>
      </geometry>
      <material name="">
        <color rgba="0.8 0.8 0.8 1"/>
      </material>
    </visual>
  </link>

  <link name="right_inner_finger">
    <inertial>
      <origin rpy="0 0 0" xyz="0.0 0.0 0.0"/>
      <mass value="0.05"/>
      <inertia ixx="1.0E-03" ixy="1.0E-06" ixz="1.0E-06" iyy="1.0E-03" iyz="1.0E-06" izz="1.0E-03"/>
    </inertial>
    <visual>
      <origin rpy="0 0 0" xyz="0 0 0"/>
      <geometry>
        <mesh filename="meshes/rg2/visual/inner_finger.stl"/>
      </geometry>
      <material name="">
        <color rgba="0.1 0.1 0.1 1"/>
      </material>
    </visual>
    <collision>
      <origin rpy="0 0 0" xyz="0 0 0"/>
      <geometry>
        <mesh filename="meshes/rg2/collision/inner_finger.stl"/>
      </geometry>
    </collision>
  </link>
  
  




############################################################





    <link name="base">
    <inertial>
      <origin xyz="0. 0. 0." rpy="0. 0. 0."/>
      <mass value="0.0001"/>
      <inertia ixx="0." ixy="0." ixz="0." iyy="0." iyz="0." izz="0."/>
    </inertial>
  </link>

  
-->

  <link name="base_link"/>

  <!-- <link name="base_link">
    <inertial>
      <origin xyz="0. 0. 0." rpy="0. 0. 0."/>
      <mass value="0.0001"/>
      <inertia ixx="0." ixy="0." ixz="0." iyy="0." iyz="0." izz="0."/>
    </inertial>
  </link> -->

  <link name="base"/>


  <link name="base_link_inertia">
    <inertial>
      <origin xyz="0. 0. 0." rpy="0. 0. 0."/>
      <mass value="4."/>
      <inertia ixx="0." ixy="0." ixz="0." iyy="0." iyz="0." izz="0."/>
    </inertial>
    <visual>
      <origin xyz="0. 0. 0." rpy="0. 0. -3.1415925"/>
      <geometry>
        <mesh filename="meshes/base_link_inertia_visuals.obj" scale="1. 1. 1."/>
      </geometry>
      <material name="LightGrey">
        <color rgba="0.7 0.7 0.7 1.0"/>
      </material>
    </visual>
    <collision>
      <origin xyz="0. 0. 0." rpy="0. 0. -3.1415925"/>
      <geometry>
        <mesh filename="meshes/base_link_inertia_collisions.obj" scale="1. 1. 1."/>
      </geometry>
    </collision>
  </link>

  <link name="shoulder_link">
    <inertial>
      <origin xyz="0. 0. 0." rpy="0. 0. 0."/>
      <mass value="3.7"/>
      <inertia ixx="0." ixy="0." ixz="0." iyy="0." iyz="0." izz="0."/>
    </inertial>
    <visual>
      <origin xyz="0. 0. 0." rpy="0. 0. -3.1415925"/>
      <geometry>
        <mesh filename="meshes/shoulder_link_visuals.obj" scale="1. 1. 1."/>
      </geometry>
      <material name="LightGrey">
        <color rgba="0.7 0.7 0.7 1.0"/>
      </material>
    </visual>
    <collision>
      <origin xyz="0. 0. 0." rpy="0. 0. -3.1415925"/>
      <geometry>
        <mesh filename="meshes/shoulder_link_collisions.obj" scale="1. 1. 1."/>
      </geometry>
    </collision>
  </link>

  <link name="upper_arm_link">
      <inertial>
        <origin xyz="0. 0. 0." rpy="0. 0. 0."/>
        <mass value="8.3929996"/>
        <inertia ixx="0." ixy="0." ixz="0." iyy="0." iyz="0." izz="0."/>
      </inertial>
      <visual>
        <origin xyz="0. 0. 0.138" rpy="1.5707964 0. -1.5707964"/>
        <geometry>
          <mesh filename="meshes/upper_arm_link_visuals.obj" scale="1. 1. 1."/>
        </geometry>
      </visual>
      <collision>
        <origin xyz="0. 0. 0.138" rpy="1.5707964 0. -1.5707964"/>
        <geometry>
          <mesh filename="meshes/upper_arm_link_collisions.obj" scale="1. 1. 1."/>
        </geometry>
      </collision>
    </link>

    <link name="forearm_link">
    <inertial>
      <origin xyz="0. 0. 0." rpy="0. 0. 0."/>
      <mass value="2.2750001"/>
      <inertia ixx="0." ixy="0." ixz="0." iyy="0." iyz="0." izz="0."/>
    </inertial>
    <visual>
      <origin xyz="0. 0. 0.007" rpy="1.5707964 0. -1.5707964"/>
      <geometry>
        <mesh filename="meshes/forearm_link_visuals.obj" scale="1. 1. 1."/>
      </geometry>
    </visual>
    <collision>
      <origin xyz="0. 0. 0.007" rpy="1.5707964 0. -1.5707964"/>
      <geometry>
        <mesh filename="meshes/forearm_link_collisions.obj" scale="1. 1. 1."/>
      </geometry>
    </collision>
  </link>

  <link name="wrist_1_link">
    <inertial>
      <origin xyz="0. 0. 0." rpy="0. 0. 0."/>
      <mass value="1.219"/>
      <inertia ixx="0." ixy="0." ixz="0." iyy="0." iyz="0." izz="0."/>
    </inertial>
    <visual>
      <origin xyz="0. 0. -0.127" rpy="1.5707964 0. 0. "/>
      <geometry>
        <mesh filename="meshes/wrist_1_link_visuals.obj" scale="1. 1. 1."/>
      </geometry>
    </visual>
    <collision>
      <origin xyz="0. 0. -0.127" rpy="1.5707964 0. 0. "/>
      <geometry>
        <mesh filename="meshes/wrist_1_link_collisions.obj" scale="1. 1. 1."/>
      </geometry>
    </collision>
  </link>


  <link name="wrist_2_link">
    <inertial>
      <origin xyz="0. 0. 0." rpy="0. 0. 0."/>
      <mass value="1.219"/>
      <inertia ixx="0." ixy="0." ixz="0." iyy="0." iyz="0." izz="0."/>
    </inertial>
    <visual>
      <origin xyz="0. 0. -0.0997" rpy="0. 0. 0."/>
      <geometry>
        <mesh filename="meshes/wrist_2_link_visuals.obj" scale="1. 1. 1."/>
      </geometry>
    </visual>
    <collision>
      <origin xyz="0. 0. -0.0997" rpy="0. 0. 0."/>
      <geometry>
        <mesh filename="meshes/wrist_2_link_collisions.obj" scale="1. 1. 1."/>
      </geometry>
    </collision>
  </link>


  <link name="wrist_3_link">
    <inertial>
      <origin xyz="0. 0. 0." rpy="0. 0. 0."/>
      <mass value="0.1879"/>
      <inertia ixx="0." ixy="0." ixz="0." iyy="0." iyz="0." izz="0."/>
    </inertial>
    <visual>
      <origin xyz="0. 0. -0.0989" rpy="1.5707964 0. 0. "/>
      <geometry>
        <mesh filename="meshes/wrist_3_link_visuals.obj" scale="1. 1. 1."/>
      </geometry>
    </visual>
    <collision>
      <origin xyz="0. 0. -0.0989" rpy="1.5707964 0. 0. "/>
      <geometry>
        <mesh filename="meshes/wrist_3_link_collisions.obj" scale="1. 1. 1."/>
      </geometry>
    </collision>

  </link>
    <link name="flange">
    <inertial>
      <origin xyz="0. 0. 0." rpy="0. 0. 0."/>
      <mass value="0.0001"/>
      <inertia ixx="0." ixy="0." ixz="0." iyy="0." iyz="0." izz="0."/>
    </inertial>
  </link>

  <link name="tool0">
    <inertial>
      <origin xyz="0. 0. 0." rpy="0. 0. 0."/>
      <mass value="0.0001"/>
      <inertia ixx="0." ixy="0." ixz="0." iyy="0." iyz="0." izz="0."/>
    </inertial>
  </link>



<!-- <link name="test"/> -->

<!-- uruf for rg2ft -->
<material name="silver">
    <color rgba="0.700 0.700 0.700 1.000"/>
  </material>
  <material name="blue">
    <color rgba="0.21568627450980393 0.592156862745098 0.8117647058823529 1.000"/>
  </material>
  <link name="quick_changer">
    <inertial>
      <origin rpy="0 0 0" xyz="0.0014673787228634701 -0.0007395056519161622 0.00391087859435364"/>
      <mass value="0.05802030412577654"/>
      <inertia ixx="2e-05" ixy="-0.0" ixz="-0.0" iyy="2.7e-05" iyz="0.0" izz="4.5e-05"/>
    </inertial>
    <visual>
      <origin rpy="0 0 0" xyz="0 0 0"/>
      <geometry>
        <mesh filename="meshes/visual/quick_changer.stl" scale="0.001 0.001 0.001"/>
      </geometry>
      <material name="blue"/>
    </visual>
    <collision>
      <origin rpy="0 0 0" xyz="0 0 0"/>
      <geometry>
        <mesh filename="meshes/collision/quick_changer.stl" scale="0.001 0.001 0.001"/>
      </geometry>
    </collision>
  </link>
  <link name="gripper_body">
    <inertial>
      <origin rpy="0 0 0" xyz="0.0272971231150397 -0.002438088956580745 0.035297715994502724"/>
      <mass value="0.5707794664902835"/>
      <inertia ixx="0.000622" ixy="3e-06" ixz="0.0" iyy="0.000662" iyz="1.8e-05" izz="0.000226"/>
    </inertial>
    <visual>
      <origin rpy="0 0 0" xyz="0.02705 -0.0 -0.047"/>
      <geometry>
        <mesh filename="meshes/visual/gripper_body.stl" scale="0.001 0.001 0.001"/>
      </geometry>
      <material name="silver"/>
    </visual>
    <collision>
      <origin rpy="0 0 0" xyz="0.02705 -0.0 -0.047"/>
      <geometry>
        <mesh filename="meshes/collision/gripper_body.stl" scale="0.001 0.001 0.001"/>
      </geometry>
    </collision>
  </link>
  <link name="angle_bracket">
    <inertial>
      <origin rpy="0 0 0" xyz="-0.00023577776357350244 0.0006406606087327927 0.01993861451986476"/>
      <mass value="0.19757034519537245"/>
      <inertia ixx="9.8e-05" ixy="-0.0" ixz="-1e-06" iyy="0.000145" iyz="2e-06" izz="0.000155"/>
    </inertial>
    <visual>
      <origin rpy="0 0 0" xyz="-0.0 -0.0 -0.00255"/>
      <geometry>
        <mesh filename="meshes/visual/angle_bracket.stl" scale="0.001 0.001 0.001"/>
      </geometry>
      <material name="silver"/>
    </visual>
    <collision>
      <origin rpy="0 0 0" xyz="-0.0 -0.0 -0.00255"/>
      <geometry>
        <mesh filename="meshes/collision/angle_bracket.stl" scale="0.001 0.001 0.001"/>
      </geometry>
    </collision>
  </link>
  <link name="left_inner_knuckle">
    <inertial>
      <origin rpy="0 0 0" xyz="0.01762916513992015 0.010471874847992522 0.017068183318320468"/>
      <mass value="0.024337519273275633"/>
      <inertia ixx="5e-06" ixy="-0.0" ixz="-3e-06" iyy="7e-06" iyz="-0.0" izz="5e-06"/>
    </inertial>
    <visual>
      <origin rpy="0 0 0" xyz="-0.0075 0.009367 -0.139397"/>
      <geometry>
        <mesh filename="meshes/visual/left_inner_knuckle.stl" scale="0.001 0.001 0.001"/>
      </geometry>
      <material name="silver"/>
    </visual>
    <!-- <collision>
      <origin rpy="0 0 0" xyz="-0.0075 0.009367 -0.139397"/>
      <geometry>
        <mesh filename="meshes/collision/left_inner_knuckle.stl" scale="0.001 0.001 0.001"/>
      </geometry>
    </collision> -->
  </link>
  <link name="right_outer_knuckle">
    <inertial>
      <origin rpy="0 0 0" xyz="-0.012312223780380358 0.010369678145266329 0.010203759185649544"/>
      <mass value="0.041583686281793396"/>
      <inertia ixx="1e-05" ixy="0.0" ixz="7e-06" iyy="1.6e-05" iyz="-0.0" izz="1e-05"/>
    </inertial>
    <visual>
      <origin rpy="0 0 0" xyz="0.017 0.009534 -0.122898"/>
      <geometry>
        <mesh filename="meshes/visual/right_outer_knuckle.stl" scale="0.001 0.001 0.001"/>
      </geometry>
      <material name="silver"/>
    </visual>
    <collision>
      <origin rpy="0 0 0" xyz="0.017 0.009534 -0.122898"/>
      <geometry>
        <mesh filename="meshes/collision/right_outer_knuckle.stl" scale="0.001 0.001 0.001"/>
      </geometry>
    </collision>
  </link>
  <link name="left_outer_knuckle">
    <inertial>
      <origin rpy="0 0 0" xyz="0.01231204747983699 0.010369678145260136 0.01020375918419171"/>
      <mass value="0.04158368628179342"/>
      <inertia ixx="1e-05" ixy="-0.0" ixz="-7e-06" iyy="1.6e-05" iyz="-0.0" izz="1e-05"/>
    </inertial>
    <visual>
      <origin rpy="0 0 0" xyz="-0.017 0.009534 -0.122898"/>
      <geometry>
        <mesh filename="meshes/visual/left_outer_knuckle.stl" scale="0.001 0.001 0.001"/>
      </geometry>
      <material name="silver"/>
    </visual>
    <collision>
      <origin rpy="0 0 0" xyz="-0.017 0.009534 -0.122898"/>
      <geometry>
        <mesh filename="meshes/collision/left_outer_knuckle.stl" scale="0.001 0.001 0.001"/>
      </geometry>
    </collision>
  </link>
  <link name="left_inner_finger">
    <inertial>
      <origin rpy="0 0 0" xyz="-0.009341477027312806 0.006108535220686467 0.03133683897712786"/>
      <mass value="0.03203868115594587"/>
      <inertia ixx="9e-06" ixy="0.0" ixz="2e-06" iyy="9e-06" iyz="-0.0" izz="2e-06"/>
    </inertial>
    <visual>
      <origin rpy="0 0 0" xyz="-0.056748 0.00475 -0.160866"/>
      <geometry>
        <mesh filename="meshes/visual/left_inner_finger.stl" scale="0.001 0.001 0.001"/>
      </geometry>
      <material name="silver"/>
    </visual>
    <collision>
      <origin rpy="0 0 0" xyz="-0.056748 0.00475 -0.160866"/>
      <geometry>
        <mesh filename="meshes/collision/left_inner_finger.stl" scale="0.001 0.001 0.001"/>
      </geometry>
    </collision>
  </link>
  <link name="right_inner_finger">
    <inertial>
      <origin rpy="0 0 0" xyz="0.009341300963273541 0.006108535097342211 0.03133683984830843"/>
      <mass value="0.032038680057528524"/>
      <inertia ixx="9e-06" ixy="-0.0" ixz="-2e-06" iyy="9e-06" iyz="-0.0" izz="2e-06"/>
    </inertial>
    <visual>
      <origin rpy="0 0 0" xyz="0.056748 0.00475 -0.160866"/>
      <geometry>
        <mesh filename="meshes/visual/right_inner_finger.stl" scale="0.001 0.001 0.001"/>
      </geometry>
      <material name="silver"/>
    </visual>
    <collision>
      <origin rpy="0 0 0" xyz="0.056748 0.00475 -0.160866"/>
      <geometry>
        <mesh filename="meshes/collision/right_inner_finger.stl" scale="0.001 0.001 0.001"/>
      </geometry>
    </collision>
  </link>
  <link name="right_inner_knuckle">
    <inertial>
      <origin rpy="0 0 0" xyz="-0.017629341439301484 0.010471874848001397 0.017068183319570135"/>
      <mass value="0.024337519273275623"/>
      <inertia ixx="5e-06" ixy="0.0" ixz="3e-06" iyy="7e-06" iyz="-0.0" izz="5e-06"/>
    </inertial>
    <visual>
      <origin rpy="0 0 0" xyz="0.0075 0.009367 -0.139397"/>
      <geometry>
        <mesh filename="meshes/visual/right_inner_knuckle.stl" scale="0.001 0.001 0.001"/>
      </geometry>
      <material name="silver"/>
    </visual>
    <!-- <collision>
      <origin rpy="0 0 0" xyz="0.0075 0.009367 -0.139397"/>
      <geometry>
        <mesh filename="meshes/collision/right_inner_knuckle.stl" scale="0.001 0.001 0.001"/>
      </geometry>
    </collision> -->
  </link>
  <joint name="quick_changer_joint" type="fixed">
    <parent link="flange"/>
    <child link="quick_changer"/>
    <origin rpy="0 1.5707 0" xyz="0 0 0"/>
  </joint>
  <joint name="gripper_body_joint" type="fixed">
    <origin rpy="0.010122909661567111 0 0" xyz="-0.02705 0.0 0.04445"/>
    <parent link="angle_bracket"/>
    <child link="gripper_body"/>
  </joint>
  <joint name="angle_bracket_joint" type="fixed">
    <origin rpy="0 0 0" xyz="0.0 0.0 0.00255"/>
    <parent link="quick_changer"/>
    <child link="angle_bracket"/>
  </joint>
  <joint name="left_inner_knuckle_joint" type="revolute">
    <origin rpy="0 0.4153883619746504 0" xyz="0.03455 -0.009367 0.092397"/>
    <parent link="gripper_body"/>
    <child link="left_inner_knuckle"/>
    <axis xyz="-0.0 0.999949 -0.010122"/>
    <limit effort="50.0" lower="-1.19" upper="0.01" velocity="2.0"/>
    <mimic joint="finger_joint" multiplier="-1" offset="0"/>
  </joint>
  <joint name="finger_joint" type="revolute">
    <origin rpy="0 -0.4153883619746504 0" xyz="0.01005 -0.009534 0.075898"/>
    <parent link="gripper_body"/>
    <child link="right_outer_knuckle"/>
    <axis xyz="-0.0 0.999949 -0.010122"/>
    <limit effort="50.0" lower="0" upper="1.18" velocity="2.0"/>
  </joint>
  <joint name="left_outer_knuckle_joint" type="revolute">
    <origin rpy="0 0.4153883619746504 0" xyz="0.04405 -0.009534 0.075898"/>
    <parent link="gripper_body"/>
    <child link="left_outer_knuckle"/>
    <axis xyz="-0.0 0.999949 -0.010122"/>
    <limit effort="50.0" lower="-1.19" upper="0.01" velocity="2.0"/>
    <mimic joint="finger_joint" multiplier="-1" offset="0"/>
  </joint>
  <joint name="left_inner_finger_joint" type="revolute">
    <origin rpy="0 -0.4153883619746504 0" xyz="0.039748 0.004784 0.037968"/>
    <parent link="left_outer_knuckle"/>
    <child link="left_inner_finger"/>
    <axis xyz="0.0 -0.999949 0.010122"/>
    <limit effort="50.0" lower="-1.19" upper="0.01" velocity="2.0"/>
    <mimic joint="finger_joint" multiplier="-1" offset="0"/>
  </joint>
  <joint name="right_inner_finger_joint" type="revolute">
    <origin rpy="0 0.4153883619746504 0" xyz="-0.039748 0.004784 0.037968"/>
    <parent link="right_outer_knuckle"/>
    <child link="right_inner_finger"/>
    <axis xyz="0.0 0.999949 -0.010122"/>
    <limit effort="50.0" lower="-1.19" upper="0.01" velocity="2.0"/>
    <mimic joint="finger_joint" multiplier="-1" offset="0"/>
  </joint>
  <joint name="right_inner_knuckle_joint" type="revolute">
    <origin rpy="0 -0.4153883619746504 0" xyz="0.01955 -0.009367 0.092397"/>
    <parent link="gripper_body"/>
    <child link="right_inner_knuckle"/>
    <axis xyz="-0.0 0.999949 -0.010122"/>
    <limit effort="50.0" lower="-0.01" upper="1.19" velocity="2.0"/>
    <mimic joint="finger_joint" multiplier="1" offset="0"/>
  </joint>

</robot>
