<?xml version="1.0" ?>
<!-- =================================================================================== -->
<!-- |    This document was autogenerated by xacro from xMatePro7.xacro                | -->
<!-- |    EDITING THIS FILE BY HAND IS NOT RECOMMENDED                                 | -->
<!-- =================================================================================== -->
<!-- xmate3 manipulator -->
<!--  Attention!!! inertia in the model is not correct!!! -->
<robot name="xMatePro7">
  <!-- Constants for robot dimensions -->
  <material name="black">
    <color rgba="0.0 0.0 0.0 1.0"/>
  </material>
  <material name="blue">
    <color rgba="0.0 0.0 0.8 1.0"/>
  </material>
  <material name="green">
    <color rgba="0.0 0.8 0.0 1.0"/>
  </material>
  <material name="grey">
    <color rgba="0.2 0.2 0.2 1.0"/>
  </material>
  <material name="orange">
    <color rgba="1.0 0.4235294117647059 0.0392156862745098 1.0"/>
  </material>
  <material name="brown">
    <color rgba="0.8705882352941177 0.8117647058823529 0.7647058823529411 1.0"/>
  </material>
  <material name="red">
    <color rgba="0.8 0.0 0.0 1.0"/>
  </material>
  <material name="white">
    <color rgba="1.0 1.0 1.0 1.0"/>
  </material>
  <material name="Beige">
    <color rgba="1.0 0.784 0.5765 1.0"/>
  </material>
  <!-- Used for fixing robot to Gazebo 'base_link' -->
  <link name="world"/>
  <joint name="fixed" type="fixed">
    <parent link="world"/>
    <child link="xMatePro7_base"/>
  </joint>
  <!--base-->
  <link name="xMatePro7_base">
    <visual>
      <geometry>
        <mesh filename="package://rokae_description/meshes/xMateER7p/visual/xMatePro7_base.stl" scale="0.001 0.001 0.001"/>
      </geometry>
      <origin rpy="0 0 0" xyz="0.0 0.0 0.0"/>
      <material name="white"/>
    </visual>
    <inertial>
      <mass value="5.48267"/>
      <inertia ixx="0.056" ixy="0" ixz="0" iyy="0.066" iyz="0" izz="0.035"/>
      <origin rpy="0 0 0" xyz="-0.0183 0 0.067"/>
    </inertial>
    <collision>
      <geometry>
        <mesh filename="package://rokae_description/meshes/xMateER7p/collision/xMatePro7_base.stl" scale="0.001 0.001 0.001"/>
      </geometry>
      <origin rpy="0 0 0" xyz="0.0 0.0 0.0"/>
    </collision>
  </link>
  <joint name="joint1" type="revolute">
    <parent link="xMatePro7_base"/>
    <child link="xMatePro7_link1"/>
    <limit effort="300" lower="-3.0527" upper="3.0527" velocity="10"/>
    <axis xyz="0 0 1"/>
    <origin rpy="0 0 0" xyz="0 0 0"/>
  </joint>
  <transmission name="tran1">
    <type>transmission_interface/SimpleTransmission</type>
    <joint name="xmate_joint_1">
      <hardwareInterface>EffortJointInterface</hardwareInterface>
    </joint>
    <actuator name="motor1">
      <hardwareInterface>EffortJointInterface</hardwareInterface>
      <mechanicalReduction>1</mechanicalReduction>
    </actuator>
  </transmission>
  <!--link 1-->
  <link name="xMatePro7_link1">
    <visual>
      <geometry>
        <mesh filename="package://rokae_description/meshes/xMateER7p/visual/xMatePro7_link1.stl" scale="0.001 0.001 0.001"/>
      </geometry>
      <origin rpy="0 0 0" xyz="0 0 0"/>
      <material name="white"/>
    </visual>
    <inertial>
      <mass value="5.96204"/>
      <inertia ixx="0.051" ixy="0" ixz="0" iyy="0.049" iyz="-0.007" izz="7.176"/>
      <origin rpy="0 0 0" xyz="0 -0.017 0.320"/>
    </inertial>
    <collision>
      <geometry>
        <mesh filename="package://rokae_description/meshes/xMateER7p/collision/xMatePro7_link1.stl" scale="0.001 0.001 0.001"/>
      </geometry>
      <origin rpy="0 0 0" xyz="0 0 0"/>
    </collision>
  </link>
  <joint name="joint2" type="revolute">
    <parent link="xMatePro7_link1"/>
    <child link="xMatePro7_link2"/>
    <limit effort="300" lower="-2.0933" upper="2.0933" velocity="10"/>
    <axis xyz="0 1 0"/>
    <origin rpy="0 0 0" xyz="0 0 0.404"/>
  </joint>
  <transmission name="tran2">
    <type>transmission_interface/SimpleTransmission</type>
    <joint name="xmate_joint_2">
      <hardwareInterface>EffortJointInterface</hardwareInterface>
    </joint>
    <actuator name="motor2">
      <hardwareInterface>EffortJointInterface</hardwareInterface>
      <mechanicalReduction>1</mechanicalReduction>
    </actuator>
  </transmission>
  <!--link 2-->
  <link name="xMatePro7_link2">
    <visual>
      <geometry>
        <mesh filename="package://rokae_description/meshes/xMateER7p/visual/xMatePro7_link2.stl" scale="0.001 0.001 0.001"/>
      </geometry>
      <origin rpy="0 0 0" xyz="0 0 0.0"/>
      <material name="white"/>
    </visual>
    <inertial>
      <mass value="5.40302"/>
      <inertia ixx="0.070" ixy="0" ixz="0" iyy="7.230" iyz="-0.014" izz="0.011"/>
      <origin rpy="0 0 0" xyz="0 0.032 0.093"/>
    </inertial>
    <collision>
      <geometry>
        <mesh filename="package://rokae_description/meshes/xMateER7p/collision/xMatePro7_link2.stl" scale="0.001 0.001 0.001"/>
      </geometry>
      <origin rpy="0 0 0" xyz="0 0 0.0"/>
    </collision>
  </link>
  <joint name="joint3" type="revolute">
    <parent link="xMatePro7_link2"/>
    <child link="xMatePro7_link3"/>
    <limit effort="300" lower="-3.0527" upper="3.0527" velocity="10"/>
    <axis xyz="0 0 1"/>
    <origin rpy="0 0 0" xyz="0 0 0.23743878"/>
  </joint>
  <transmission name="tran3">
    <type>transmission_interface/SimpleTransmission</type>
    <joint name="xmate_joint_3">
      <hardwareInterface>EffortJointInterface</hardwareInterface>
    </joint>
    <actuator name="motor3">
      <hardwareInterface>EffortJointInterface</hardwareInterface>
      <mechanicalReduction>1</mechanicalReduction>
    </actuator>
  </transmission>
  <!--${nameofManipulator}_link 3-->
  <link name="xMatePro7_link3">
    <visual>
      <geometry>
        <mesh filename="package://rokae_description/meshes/xMateER7p/visual/xMatePro7_link3.stl" scale="0.001 0.001 0.001"/>
      </geometry>
      <origin rpy="0 0 0" xyz="0 0 0.15549959"/>
      <material name="white"/>
    </visual>
    <inertial>
      <mass value="3.95735"/>
      <inertia ixx="0.022" ixy="0" ixz="0" iyy="0.021" iyz="-0.002" izz="1.12"/>
      <origin rpy="0 0 0" xyz="0 -0.013 -0.067"/>
    </inertial>
    <collision>
      <geometry>
        <mesh filename="package://rokae_description/meshes/xMateER7p/collision/xMatePro7_link3.stl" scale="0.001 0.001 0.001"/>
      </geometry>
      <origin rpy="0 0 0" xyz="0 0 0.15549959"/>
    </collision>
  </link>
  <joint name="joint4" type="revolute">
    <parent link="xMatePro7_link3"/>
    <child link="xMatePro7_link4"/>
    <limit effort="300" lower="-2.0933" upper="2.0933" velocity="10"/>
    <!--     lower="-2.79" upper="2.79" -->
    <axis xyz="0 1 0"/>
    <!--     <origin rpy="0 0 0" xyz="0.585 0.0 0.035"/> -->
    <origin rpy="0 0 0" xyz="0 0 0.15549959"/>
  </joint>
  <transmission name="tran4">
    <type>transmission_interface/SimpleTransmission</type>
    <joint name="xmate_joint_4">
      <hardwareInterface>EffortJointInterface</hardwareInterface>
    </joint>
    <actuator name="motor4">
      <hardwareInterface>EffortJointInterface</hardwareInterface>
      <mechanicalReduction>1</mechanicalReduction>
    </actuator>
  </transmission>
  <!--link 4-->
  <link name="xMatePro7_link4">
    <visual>
      <geometry>
        <mesh filename="package://rokae_description/meshes/xMateER7p/visual/xMatePro7_link4.stl" scale=".001 0.001 0.001"/>
      </geometry>
      <origin rpy="0 0 0" xyz="0.0 0.0 0.0"/>
      <material name="white"/>
    </visual>
    <inertial>
      <mass value="2.91217"/>
      <inertia ixx="0.024" ixy="0" ixz="0" iyy="1.138" iyz="-0.004" izz="0.005"/>
      <origin rpy="0 0 0" xyz="0 0.026 0.068"/>
    </inertial>
    <collision>
      <geometry>
        <mesh filename="package://rokae_description/meshes/xMateER7p/collision/xMatePro7_link4.stl" scale="0.001 0.001 0.001"/>
      </geometry>
      <origin rpy="0 0 0" xyz="0.0 0.0 0.0"/>
    </collision>
  </link>
  <joint name="joint5" type="revolute">
    <parent link="xMatePro7_link4"/>
    <child link="xMatePro7_link5"/>
    <limit effort="300" lower="-3.0527" upper="3.0527" velocity="10"/>
    <axis xyz="0 0 1"/>
    <origin rpy="0 0 0" xyz="0 0 0.22044633"/>
  </joint>
  <transmission name="tran5">
    <type>transmission_interface/SimpleTransmission</type>
    <joint name="xmate_joint_5">
      <hardwareInterface>EffortJointInterface</hardwareInterface>
    </joint>
    <actuator name="motor5">
      <hardwareInterface>EffortJointInterface</hardwareInterface>
      <mechanicalReduction>1</mechanicalReduction>
    </actuator>
  </transmission>
  <!--link 5-->
  <link name="xMatePro7_link5">
    <visual>
      <geometry>
        <mesh filename="package://rokae_description/meshes/xMateER7p/visual/xMatePro7_link5.stl" scale="0.001 0.001 0.001"/>
      </geometry>
      <origin rpy="0 0 0" xyz="0 0 0.14512568"/>
      <material name="white"/>
    </visual>
    <inertial>
      <mass value="2.47056"/>
      <inertia ixx="0.019" ixy="0" ixz="0" iyy="0.018" iyz="-0.002" izz="0.339"/>
      <origin rpy="0 0 0" xyz="0 -0.014 -0.079"/>
    </inertial>
    <collision>
      <geometry>
        <mesh filename="package://rokae_description/meshes/xMateER7p/collision/xMatePro7_link5.stl" scale="0.001 0.001 0.001"/>
      </geometry>
      <origin rpy="0 0 0" xyz="0 0 0.14512568"/>
    </collision>
  </link>
  <joint name="joint6" type="revolute">
    <parent link="xMatePro7_link5"/>
    <child link="xMatePro7_link6"/>
    <limit effort="300" lower="-2.0933" upper="2.0933" velocity="10"/>
    <axis xyz="0 1 0"/>
    <origin rpy="0.0 0.0 0" xyz="0 0 0.14512568"/>
  </joint>
  <transmission name="tran6">
    <type>transmission_interface/SimpleTransmission</type>
    <joint name="xmate_joint_6">
      <hardwareInterface>EffortJointInterface</hardwareInterface>
    </joint>
    <actuator name="motor6">
      <hardwareInterface>EffortJointInterface</hardwareInterface>
      <mechanicalReduction>1</mechanicalReduction>
    </actuator>
  </transmission>
  <!--link 6-->
  <link name="xMatePro7_link6">
    <visual>
      <geometry>
        <mesh filename="package://rokae_description/meshes/xMateER7p/visual/xMatePro7_link6.stl" scale="0.001 0.001 0.001"/>
      </geometry>
      <origin rpy="0 0 0" xyz="0.0 0.0 0.0"/>
      <material name="white"/>
    </visual>
    <inertial>
      <mass value="2.16053"/>
      <inertia ixx="0.016" ixy="0" ixz="0" iyy="0.351" iyz="-0.003" izz="0.003"/>
      <origin rpy="0 0 0" xyz="0 0.020 0.085"/>
    </inertial>
    <collision>
      <geometry>
        <mesh filename="package://rokae_description/meshes/xMateER7p/collision/xMatePro7_link6.stl" scale="0.001 0.001 0.001"/>
      </geometry>
      <origin rpy="0 0 0" xyz="0.0 0.0 0.0"/>
    </collision>
  </link>
  <joint name="joint7" type="revolute">
    <parent link="xMatePro7_link6"/>
    <child link="xMatePro7_link7"/>
    <limit effort="300" lower="-6.283" upper="6.283" velocity="10"/>
    <axis xyz="0 0 1"/>
    <origin rpy="0.0 0.0 0.0" xyz="0 0 0.25090877"/>
  </joint>
  <transmission name="tran7">
    <type>transmission_interface/SimpleTransmission</type>
    <joint name="xmate_joint_7">
      <hardwareInterface>EffortJointInterface</hardwareInterface>
    </joint>
    <actuator name="motor7">
      <hardwareInterface>EffortJointInterface</hardwareInterface>
      <mechanicalReduction>1</mechanicalReduction>
    </actuator>
  </transmission>
  <!--link 7-->
  <link name="xMatePro7_link7">
    <visual>
      <geometry>
        <mesh filename="package://rokae_description/meshes/xMateER7p/visual/xMatePro7_link7.stl" scale="0.001 0.001 0.001"/>
      </geometry>
      <origin rpy="0 0 0" xyz="0 0 0"/>
      <material name="white"/>
    </visual>
    <inertial>
      <mass value="1.26834"/>
      <inertia ixx="0.002" ixy="-0.000000" ixz="-0.000000" iyy="0.001" iyz="-0.000000" izz="0.337"/>
      <origin rpy="0 0 0" xyz="0 0.012 -0.052"/>
    </inertial>
    <collision>
      <geometry>
        <mesh filename="package://rokae_description/meshes/xMateER7p/collision/xMatePro7_link7.stl" scale="0.001 0.001 0.001"/>
      </geometry>
      <origin rpy="0 0 0" xyz="0 0 0"/>
    </collision>
  </link>
  <link name="dh_gripper_link">
    <inertial>
      <mass value="5.5333"/>
      <inertia ixx="0.46974" ixy="-1.5672E-07" ixz="-0.0002125" iyy="0.72479" iyz="-0.0018639" izz="0.25531"/>
    </inertial>
    <visual>
      <geometry>
        <mesh filename="package://rokae_description/meshes/xMateER7p/collision/dh_gripper_300.dae"/>
      </geometry>
    </visual>
    <collision>
      <geometry>
        <mesh filename="package://rokae_description/meshes/xMateER7p/collision/dh_gripper_300.dae"/>
      </geometry>
    </collision>
  </link>
  <joint name="dh_gripper_joint" type="fixed">
    <origin rpy="1.5708 0 1.309" xyz="0 0 0"/>
    <parent link="xMatePro7_link7"/>
    <child link="dh_gripper_link"/>
  </joint>
</robot>

