<?xml version="1.0" ?>
<!-- =================================================================================== -->
<!-- |    This document was autogenerated by xacro from xMatePro7.xacro                | -->
<!-- |    EDITING THIS FILE BY HAND IS NOT RECOMMENDED                                 | -->
<!-- =================================================================================== -->
<!-- xmate3 manipulator -->
<!--  Attention!!! inertia in the model is not correct!!! -->
<robot name="multi_joint">
  <!-- Constants for robot dimensions -->
  <material name="black">
    <color rgba="0.0 0.0 0.0 1.0"/>
  </material>
  <material name="blue">
    <color rgba="0.0 0.0 0.8 1.0"/>
  </material>
  <material name="green">
    <color rgba="0.0 0.8 0.0 1.0"/>
  </material>
  <material name="grey">
    <color rgba="0.2 0.2 0.2 1.0"/>
  </material>
  <material name="orange">
    <color rgba="1.0 0.4235294117647059 0.0392156862745098 1.0"/>
  </material>
  <material name="brown">
    <color rgba="0.8705882352941177 0.8117647058823529 0.7647058823529411 1.0"/>
  </material>
  <material name="red">
    <color rgba="0.8 0.0 0.0 1.0"/>
  </material>
  <material name="white">
    <color rgba="1.0 1.0 1.0 1.0"/>
  </material>
  <material name="Beige">
    <color rgba="1.0 0.784 0.5765 1.0"/>
  </material>
  <!-- Used for fixing robot to Gazebo 'base_link' -->
  <link name="world"/>
  
  <link name="base_link">
    <visual>
      <geometry>
        <mesh filename="meshes/visual/fixture_box.obj" scale="0.2 0.2 0.2"/>
      </geometry>
      <origin rpy="0 0 0" xyz="0 0 0"/>
      <material name="white"/>
    </visual>
    <inertial>
        <density value="1000"/>
    </inertial>
    <collision>
      <geometry>
        <mesh filename="meshes/visual/fixture_box.obj" scale="0.2 0.2 0.2"/>
      </geometry>
      <origin rpy="0 0 0" xyz="0 0 0"/>
    </collision>
  </link>

  <link name="z_link">
    <visual>
      <geometry>
        <mesh filename="meshes/visual/fixture_box.obj" scale="0.15 0.15 0.15"/>
      </geometry>
      <origin rpy="0 0 0" xyz="0 0 0"/>
      <material name="white"/>
    </visual>
    <inertial>
        <density value="10000"/>
    </inertial>
    <collision>
      <geometry>
        <mesh filename="meshes/visual/fixture_box.obj" scale="0.15 0.15 0.15"/>
      </geometry>
      <origin rpy="0 0 0" xyz="0 0 0"/>
    </collision>
  </link>

  <joint name="fixed" type="fixed">
    <parent link="world"/>
    <child link="base_link"/>
  </joint>

  <joint name="z_joint" type="revolute">
    <parent link="base_link"/>
    <child link="z_link"/>
    <origin rpy="0 0 0" xyz="0 0 0.175"/>
    <axis xyz="0 0 1"/>
    <dynamics damping="10.0"/>
    <limit effort="100" lower="0.0" upper="1000" velocity="1000"/>
    <!-- <mimic joint="panda_finger_joint1"/> -->
  </joint>


</robot>

